<?xml version="1.0" ?>
<!-- =================================================================================== -->
<!-- |    This document was autogenerated by xacro from pentaxis006.urdf.xacro         | -->
<!-- |    EDITING THIS FILE BY HAND IS NOT RECOMMENDED                                 | -->
<!-- =================================================================================== -->
<!-- Revolute-Revolute Manipulator -->
<robot name="pentaxis" xmlns:xacro="http://www.ros.org/wiki/xacro">
  <!-- Denavit-Hartenberg parameters -->
  <!-- not implemented -->
  <!-- OG: 0.252 -->
  <!-- not implemented -->
  <!-- -0.87+2*PI -->
  <!-- 1.50 -->
  <!-- 2.50 -->
  <!-- not implemented -->
  <link name="base_footprint">
    <visual>
      <origin rpy="0 0 0" xyz="0 0 0"/>
      <geometry>
        <box size="0.001 0.001 0.001"/>
      </geometry>
    </visual>
  </link>
  <joint name="base_footprint_joint" type="fixed">
    <origin rpy="0 0 0" xyz="0 0 0"/>
    <child link="base_link"/>
    <parent link="base_footprint"/>
  </joint>
  <link name="base_link">
    <visual>
      <geometry>
        <cylinder length="0.152" radius="0.0469507"/>
      </geometry>
      <origin rpy="0 0 0" xyz="0 0 0.076"/>
      <material name="blue1">
        <color rgba="0 0.2 1 1"/>
      </material>
    </visual>
  </link>
  <link name="link1">
    <!-- motor (in red) -->
    <visual>
      <geometry>
        <cylinder length="0.11" radius="0.0469507"/>
      </geometry>
      <origin rpy="0 0 0" xyz="0 0 0"/>
      <material name="red1">
        <color rgba="1 0 0.2 1"/>
      </material>
    </visual>
    <!--  -->
  </link>
  <!-- JOINT1 Base - Link1 -->
  <joint name="base_link_to_link1" type="revolute">
    <axis xyz="0 0 1"/>
    <limit effort="1000.0" lower="-2.5" upper="2.5" velocity="0.5"/>
    <parent link="base_link"/>
    <child link="link1"/>
    <!--z=base_link.length+link1.length/2 -->
    <origin xyz="0 0 0.207"/>
  </joint>
  <!-- Link 1_1 -->
  <link name="link1_1">
    <visual>
      <geometry>
        <cylinder length="0.06" radius="0.02"/>
      </geometry>
      <origin rpy="1.57079632679 0 0" xyz="0 0 0"/>
      <material name="blue2">
        <color rgba="0 0.4 1 1"/>
      </material>
    </visual>
  </link>
  <!-- -->
  <joint name="link1_to_link1_1" type="fixed">
    <parent link="link1"/>
    <child link="link1_1"/>
    <origin rpy="0 0 0" xyz="0 0.0769507 -0.035"/>
  </joint>
  <link name="link1_2">
    <visual>
      <geometry>
        <cylinder length="0.259" radius="0.02"/>
      </geometry>
      <origin rpy="0 0 0" xyz="0 0 0"/>
      <material name="blue2">
        <color rgba="0 0.4 1 1"/>
      </material>
    </visual>
  </link>
  <!-- -->
  <joint name="link1_1_to_link1_2" type="fixed">
    <axis xyz="0 0 0"/>
    <parent link="link1_1"/>
    <child link="link1_2"/>
    <!-- z=link1_2.length/2 - link1_1.radius = 0.1095 -->
    <!-- y=-link1_1.length/2 = -0.03 -->
    <origin rpy="0 0 0" xyz="0 0.03 0.1095"/>
  </joint>
  <!-- %%%%%%%%%%%%%%%%%%%%%%%%%%%%%%%%%%%%%%%%%%%%%%%%%%%%%% -->
  <!-- Link 2 -->
  <link name="link2">
    <visual>
      <geometry>
        <cylinder length="0.09" radius="0.02"/>
      </geometry>
      <origin rpy="1.57079632679 0 0" xyz="0 0 0"/>
      <material name="red1">
        <color rgba="1 0 0.2 1"/>
      </material>
    </visual>
  </link>
  <!-- -->
  <joint name="link1_to_link2" type="revolute">
    <axis xyz="0 1 0"/>
    <limit effort="1000.0" lower="-3.14159" upper="1.1" velocity="0.5"/>
    <parent link="link1_2"/>
    <child link="link2"/>
    <!-- y=link2.length/2 - link2.radius = 0.025 -->
    <!-- z=link1_2/2 = 0.1295 -->
    <origin rpy="0 0.0 0" xyz="0 -0.025 0.1295"/>
  </joint>
  <!-- link2_1 -->
  <link name="link2_1">
    <visual>
      <geometry>
        <cylinder length="0.392" radius="0.02"/>
      </geometry>
      <!-- <origin rpy="0 0 0" xyz="0 0 0.056"/> -->
      <origin rpy="0 1.57079632679 0" xyz="0 0 0"/>
      <material name="blue2">
        <color rgba="0 0.4 1 1"/>
      </material>
    </visual>
  </link>
  <!-- -->
  <joint name="link2_to_link2_1" type="fixed">
    <axis xyz="0 0 0"/>
    <parent link="link2"/>
    <child link="link2_1"/>
    <!-- y=link2.length/2 - link2_1.radius/2 = -0.025 -->
    <!-- x=link2_1.length/2 - 0.140 = 0.056 -->
    <origin rpy="0 0 0" xyz="0.056 -0.025 0"/>
  </joint>
  <!-- %%%%%%%%%%%%%%%%%%%%%%%%%%%%%%%%%%%%%%%%%%%%%%%%%%%%%% -->
  <!-- Link 3 -->
  <link name="link3">
    <visual>
      <geometry>
        <cylinder length="0.09" radius="0.02"/>
      </geometry>
      <origin rpy="-1.57079632679 0 0" xyz="0 0 0"/>
      <material name="red1">
        <color rgba="1 0 0.2 1"/>
      </material>
    </visual>
  </link>
  <!-- -->
  <joint name="link2_to_link3" type="revolute">
    <axis xyz="0 1 0"/>
    <limit effort="1000.0" lower="-2.15" upper="2.15" velocity="0.5"/>
    <parent link="link2_1"/>
    <child link="link3"/>
    <!-- y=-link2_1.length/2 - 0.0069507 -->
    <!-- x=link3.length/2 - link2_1.radius -->
    <origin rpy="0 0.0 0" xyz="0.196 -0.0319507 0"/>
  </joint>
  <!-- link3_1 -->
  <link name="link3_1">
    <visual>
      <geometry>
        <cylinder length="0.39" radius="0.02"/>
      </geometry>
      <origin rpy="0 1.57079632679 0" xyz="0 0 0"/>
      <material name="blue2">
        <color rgba="0 0.4 1 1"/>
      </material>
    </visual>
  </link>
  <!-- -->
  <joint name="link3_to_link3_1" type="fixed">
    <axis xyz="0 0 0"/>
    <parent link="link3"/>
    <child link="link3_1"/>
    <!-- y=link3.length/2 - link3_1.radius-->
    <!-- x=link3_1/2 - 0.140 -->
    <origin rpy="0 0 0" xyz="0.055 -0.025 0"/>
  </joint>
  <!-- %%%%%%%%%%%%%%%%%%%%%%%%%%%%%%%%%%%%%%%%%%%%%%%%%%%%%% -->
  <link name="link4">
    <visual>
      <geometry>
        <sphere radius="0.02"/>
      </geometry>
      <origin rpy="0 0 0" xyz="0 0 0"/>
      <material name="red1">
        <color rgba="1 0 0.2 1"/>
      </material>
    </visual>
  </link>
  <!-- -->
  <joint name="link3_to_link4" type="revolute">
    <axis xyz="0 1 0"/>
    <limit effort="1000.0" lower="0" upper="3.14159" velocity="0.5"/>
    <parent link="link3_1"/>
    <child link="link4"/>
    <!-- z=link3_1.length/2 -->
    <origin rpy="0 0.0 0" xyz="0.195 0 0"/>
  </joint>
  <!-- %%%%%%%%%%%%%%%%%%%%%%%%%%%%%%%%%%%%%%%%%%%%%%%%%%%%%% -->
  <link name="link5">
    <visual>
      <geometry>
        <cylinder length="0.035" radius="0.016"/>
      </geometry>
      <!-- <origin rpy="0 0 0" xyz="0 0 0"/> -->
      <!-- z=link5.length/2 -->
      <origin rpy="0 0 0" xyz="0 0 0.002"/>
      <material name="color2">
        <color rgba="1 1 1 1"/>
      </material>
    </visual>
  </link>
  <joint name="link4_to_link5_mimic" type="revolute">
  	<axis xyz="0 0 1"/>
  	<mimic joint="link3_to_link4" multiplier="1.0" offset="0.0" />
  	<parent link="link4"/>
    <child link="link5"/>
    <limit effort="1000.0" lower="-1.570796327" upper="1.570796327" velocity="0.5"/>
    <origin rpy="0 0 0" xyz="0 0 0.035"/>
  </joint>
  <joint name="link4_to_link5" type="revolute">
    <axis xyz="0 0 1"/>

    <!-- <mimic joint="eef2_to_eef_left" multiplier="1.0" offset="0.0"/> -->
    <limit effort="1000.0" lower="-1.570796327" upper="1.570796327" velocity="0.5"/>
    <parent link="link4"/>
    <child link="link5"/>
    <!-- <origin rpy="0 0 0" xyz="0 0 0.0275"/> -->
    <origin rpy="0 0 0" xyz="0 0 0.035"/>
    
  </joint>
  <!-- %%%%%%%%%%%%%%%%%%%%%%%%%%%%%%%%%%%%%%%%%%%%%%%%%%%%%% -->
  <link name="eef1">
    <visual>
      <geometry>
        <box size="0.05 0.04 0.055"/>
      </geometry>
      <origin rpy="0 0 0" xyz="0 0 0"/>
      <material name="color3">
        <color rgba="0.2 0.2 0.2 1"/>
      </material>
    </visual>
  </link>
  <joint name="link5_to_eef1" type="fixed">
    <parent link="link5"/>
    <child link="eef1"/>
    <!-- z=?-->
    <origin rpy="0 0 -1.570796327" xyz="0 0 0.047"/>
  </joint>
  <link name="eef2">
    <visual>
      <geometry>
        <box size="0.11 0.02 0.025"/>
      </geometry>
      <origin rpy="0 0 0" xyz="0 0 0"/>
      <material name="color3">
        <color rgba="0.2 0.2 0.2 1"/>
      </material>
    </visual>
  </link>
  <joint name="eef1_to_eef2" type="fixed">
    <parent link="eef1"/>
    <child link="eef2"/>
    <origin rpy="0 0 0" xyz="0 0 0.04"/>
  </joint>
  <link name="eef_left">
    <visual>
      <geometry>
        <box size="0.02 0.02 0.07"/>
      </geometry>
      <origin rpy="0 0 0" xyz="0 0 0"/>
      <material name="color3">
        <color rgba="0.2 0.2 0.2 1"/>
      </material>
    </visual>
  </link>
  <joint name="eef2_to_eef_left" type="prismatic">
    <axis xyz="1 0 0"/>
    <limit effort="1000.0" lower="-0.045" upper="0" velocity="0.5"/>
    <parent link="eef2"/>
    <child link="eef_left"/>
    <origin rpy="0 0 0" xyz="0.045 0 0.0475"/>
  </joint>
  <link name="eef_right">
    <visual>
      <geometry>
        <box size="0.02 0.02 0.07"/>
      </geometry>
      <origin rpy="0 0 0" xyz="0 0 0"/>
      <material name="color3">
        <color rgba="0.2 0.2 0.2 1"/>
      </material>
    </visual>
  </link>
  <joint name="eef2_to_eef_right" type="prismatic">
    <axis xyz="-1 0 0"/>
    <limit effort="1000.0" lower="-0.045" upper="0" velocity="0.5"/>
    <mimic joint="eef2_to_eef_left" multiplier="1.0" offset="0.0"/>
    <parent link="eef2"/>
    <child link="eef_right"/>
    <origin rpy="0 0 0" xyz="-0.045 0 0.0475"/>
  </joint>
</robot>

